<?xml version="1.0" encoding="UTF-8"?>
<testng-results retried="10" ignored="0" total="15" passed="3" failed="2" skipped="0">
  <reporter-output>
  </reporter-output>
  <suite started-at="2022-10-15T00:11:04 IST" name="Suite" finished-at="2022-10-15T00:11:39 IST" duration-ms="34945">
    <groups>
      <group name="recursionTest">
        <method signature="NewTest.testMultipleUserDetials(java.lang.String,java.lang.String)[pri:1, instance:testng.NewTest@378542de]" name="testMultipleUserDetials" class="testng.NewTest"/>
      </group> <!-- recursionTest -->
      <group name="smokeTest">
        <method signature="NewTest.validLogin(java.lang.String,java.lang.String)[pri:0, instance:testng.NewTest@378542de]" name="validLogin" class="testng.NewTest"/>
      </group> <!-- smokeTest -->
    </groups>
    <test started-at="2022-10-15T00:11:04 IST" name="Test" finished-at="2022-10-15T00:11:39 IST" duration-ms="34945">
      <class name="testng.NewTest">
        <test-method is-config="true" signature="beforeSuite()[pri:0, instance:testng.NewTest@378542de]" started-at="2022-10-15T00:10:37 IST" name="beforeSuite" finished-at="2022-10-15T00:11:04 IST" duration-ms="26828" status="PASS">
          <reporter-output>
          </reporter-output>
        </test-method> <!-- beforeSuite -->
        <test-method is-config="true" signature="beforeTest()[pri:0, instance:testng.NewTest@378542de]" started-at="2022-10-15T00:11:04 IST" name="beforeTest" finished-at="2022-10-15T00:11:04 IST" duration-ms="172" status="PASS">
          <reporter-output>
          </reporter-output>
        </test-method> <!-- beforeTest -->
        <test-method is-config="true" signature="beforeMethod()[pri:0, instance:testng.NewTest@378542de]" started-at="2022-10-15T00:11:04 IST" name="beforeMethod" finished-at="2022-10-15T00:11:11 IST" duration-ms="7231" status="PASS">
          <reporter-output>
          </reporter-output>
        </test-method> <!-- beforeMethod -->
        <test-method signature="validLogin(java.lang.String,java.lang.String)[pri:0, instance:testng.NewTest@378542de]" started-at="2022-10-15T00:11:11 IST" name="validLogin" finished-at="2022-10-15T00:11:19 IST" duration-ms="7281" status="PASS">
          <params>
            <param index="0">
              <value>
                <![CDATA[standard_user]]>
              </value>
            </param>
            <param index="1">
              <value>
                <![CDATA[secret_sauce]]>
              </value>
            </param>
          </params>
          <reporter-output>
          </reporter-output>
        </test-method> <!-- validLogin -->
        <test-method is-config="true" signature="beforeMethod()[pri:0, instance:testng.NewTest@378542de]" started-at="2022-10-15T00:11:24 IST" name="beforeMethod" finished-at="2022-10-15T00:11:24 IST" duration-ms="301" status="PASS">
          <reporter-output>
          </reporter-output>
        </test-method> <!-- beforeMethod -->
        <test-method signature="testMultipleUserDetials(java.lang.String,java.lang.String)[pri:1, instance:testng.NewTest@378542de]" started-at="2022-10-15T00:11:24 IST" name="testMultipleUserDetials" data-provider="loginDetails" finished-at="2022-10-15T00:11:25 IST" depends-on-methods="testng.NewTest.validLogin" duration-ms="1057" status="PASS">
          <params>
            <param index="0">
              <value>
                <![CDATA[standard_user]]>
              </value>
            </param>
            <param index="1">
              <value>
                <![CDATA[secret_sauce]]>
              </value>
            </param>
          </params>
          <reporter-output>
          </reporter-output>
        </test-method> <!-- testMultipleUserDetials -->
        <test-method is-config="true" signature="beforeMethod()[pri:0, instance:testng.NewTest@378542de]" started-at="2022-10-15T00:11:25 IST" name="beforeMethod" finished-at="2022-10-15T00:11:25 IST" duration-ms="204" status="PASS">
          <reporter-output>
          </reporter-output>
        </test-method> <!-- beforeMethod -->
        <test-method retried="true" signature="testMultipleUserDetials(java.lang.String,java.lang.String)[pri:1, instance:testng.NewTest@378542de]" started-at="2022-10-15T00:11:25 IST" name="testMultipleUserDetials" data-provider="loginDetails" finished-at="2022-10-15T00:11:27 IST" depends-on-methods="testng.NewTest.validLogin" duration-ms="1276" status="SKIP">
          <params>
            <param index="0">
              <value>
                <![CDATA[locked_out_user]]>
              </value>
            </param>
            <param index="1">
              <value>
                <![CDATA[rrr]]>
              </value>
            </param>
          </params>
          <exception class="java.lang.AssertionError">
            <message>
              <![CDATA[expected [true] but found [false]]]>
            </message>
            <full-stacktrace>
              <![CDATA[java.lang.AssertionError: expected [true] but found [false]
at org.testng.Assert.fail(Assert.java:110)
at org.testng.Assert.failNotEquals(Assert.java:1413)
at org.testng.Assert.assertEqualsImpl(Assert.java:149)
at org.testng.Assert.assertEquals(Assert.java:131)
at org.testng.Assert.assertEquals(Assert.java:1020)
at testng.NewTest.testMultipleUserDetials(NewTest.java:48)
at java.base/jdk.internal.reflect.DirectMethodHandleAccessor.invoke(DirectMethodHandleAccessor.java:104)
at java.base/java.lang.reflect.Method.invoke(Method.java:578)
at org.testng.internal.invokers.MethodInvocationHelper.invokeMethod(MethodInvocationHelper.java:139)
at org.testng.internal.invokers.TestInvoker.invokeMethod(TestInvoker.java:677)
at org.testng.internal.invokers.TestInvoker.invokeTestMethod(TestInvoker.java:221)
at org.testng.internal.invokers.MethodRunner.runInSequence(MethodRunner.java:50)
at org.testng.internal.invokers.TestInvoker$MethodInvocationAgent.invoke(TestInvoker.java:962)
at org.testng.internal.invokers.TestInvoker.invokeTestMethods(TestInvoker.java:194)
at org.testng.internal.invokers.TestMethodWorker.invokeTestMethods(TestMethodWorker.java:148)
at org.testng.internal.invokers.TestMethodWorker.run(TestMethodWorker.java:128)
at java.base/java.util.ArrayList.forEach(ArrayList.java:1511)
at org.testng.TestRunner.privateRun(TestRunner.java:806)
at org.testng.TestRunner.run(TestRunner.java:601)
at org.testng.SuiteRunner.runTest(SuiteRunner.java:433)
at org.testng.SuiteRunner.runSequentially(SuiteRunner.java:427)
at org.testng.SuiteRunner.privateRun(SuiteRunner.java:387)
at org.testng.SuiteRunner.run(SuiteRunner.java:330)
at org.testng.SuiteRunnerWorker.runSuite(SuiteRunnerWorker.java:52)
at org.testng.SuiteRunnerWorker.run(SuiteRunnerWorker.java:95)
at org.testng.TestNG.runSuitesSequentially(TestNG.java:1256)
at org.testng.TestNG.runSuitesLocally(TestNG.java:1176)
at org.testng.TestNG.runSuites(TestNG.java:1099)
at org.testng.TestNG.run(TestNG.java:1067)
at org.testng.remote.AbstractRemoteTestNG.run(AbstractRemoteTestNG.java:115)
at org.testng.remote.RemoteTestNG.initAndRun(RemoteTestNG.java:251)
at org.testng.remote.RemoteTestNG.main(RemoteTestNG.java:77)
]]>
            </full-stacktrace>
          </exception> <!-- java.lang.AssertionError -->
          <reporter-output>
          </reporter-output>
        </test-method> <!-- testMultipleUserDetials -->
        <test-method is-config="true" signature="beforeMethod()[pri:0, instance:testng.NewTest@378542de]" started-at="2022-10-15T00:11:27 IST" name="beforeMethod" finished-at="2022-10-15T00:11:27 IST" duration-ms="149" status="PASS">
          <reporter-output>
          </reporter-output>
        </test-method> <!-- beforeMethod -->
        <test-method retried="true" signature="testMultipleUserDetials(java.lang.String,java.lang.String)[pri:1, instance:testng.NewTest@378542de]" started-at="2022-10-15T00:11:27 IST" name="testMultipleUserDetials" data-provider="loginDetails" finished-at="2022-10-15T00:11:28 IST" depends-on-methods="testng.NewTest.validLogin" duration-ms="1073" status="SKIP">
          <params>
            <param index="0">
              <value>
                <![CDATA[locked_out_user]]>
              </value>
            </param>
            <param index="1">
              <value>
                <![CDATA[rrr]]>
              </value>
            </param>
          </params>
          <exception class="java.lang.AssertionError">
            <message>
              <![CDATA[expected [true] but found [false]]]>
            </message>
            <full-stacktrace>
              <![CDATA[java.lang.AssertionError: expected [true] but found [false]
at org.testng.Assert.fail(Assert.java:110)
at org.testng.Assert.failNotEquals(Assert.java:1413)
at org.testng.Assert.assertEqualsImpl(Assert.java:149)
at org.testng.Assert.assertEquals(Assert.java:131)
at org.testng.Assert.assertEquals(Assert.java:1020)
at testng.NewTest.testMultipleUserDetials(NewTest.java:48)
at java.base/jdk.internal.reflect.DirectMethodHandleAccessor.invoke(DirectMethodHandleAccessor.java:104)
at java.base/java.lang.reflect.Method.invoke(Method.java:578)
at org.testng.internal.invokers.MethodInvocationHelper.invokeMethod(MethodInvocationHelper.java:139)
at org.testng.internal.invokers.TestInvoker.invokeMethod(TestInvoker.java:677)
at org.testng.internal.invokers.TestInvoker.retryFailed(TestInvoker.java:263)
at org.testng.internal.invokers.MethodRunner.runInSequence(MethodRunner.java:62)
at org.testng.internal.invokers.TestInvoker$MethodInvocationAgent.invoke(TestInvoker.java:962)
at org.testng.internal.invokers.TestInvoker.invokeTestMethods(TestInvoker.java:194)
at org.testng.internal.invokers.TestMethodWorker.invokeTestMethods(TestMethodWorker.java:148)
at org.testng.internal.invokers.TestMethodWorker.run(TestMethodWorker.java:128)
at java.base/java.util.ArrayList.forEach(ArrayList.java:1511)
at org.testng.TestRunner.privateRun(TestRunner.java:806)
at org.testng.TestRunner.run(TestRunner.java:601)
at org.testng.SuiteRunner.runTest(SuiteRunner.java:433)
at org.testng.SuiteRunner.runSequentially(SuiteRunner.java:427)
at org.testng.SuiteRunner.privateRun(SuiteRunner.java:387)
at org.testng.SuiteRunner.run(SuiteRunner.java:330)
at org.testng.SuiteRunnerWorker.runSuite(SuiteRunnerWorker.java:52)
at org.testng.SuiteRunnerWorker.run(SuiteRunnerWorker.java:95)
at org.testng.TestNG.runSuitesSequentially(TestNG.java:1256)
at org.testng.TestNG.runSuitesLocally(TestNG.java:1176)
at org.testng.TestNG.runSuites(TestNG.java:1099)
at org.testng.TestNG.run(TestNG.java:1067)
at org.testng.remote.AbstractRemoteTestNG.run(AbstractRemoteTestNG.java:115)
at org.testng.remote.RemoteTestNG.initAndRun(RemoteTestNG.java:251)
at org.testng.remote.RemoteTestNG.main(RemoteTestNG.java:77)
]]>
            </full-stacktrace>
          </exception> <!-- java.lang.AssertionError -->
          <reporter-output>
          </reporter-output>
        </test-method> <!-- testMultipleUserDetials -->
        <test-method is-config="true" signature="beforeMethod()[pri:0, instance:testng.NewTest@378542de]" started-at="2022-10-15T00:11:28 IST" name="beforeMethod" finished-at="2022-10-15T00:11:28 IST" duration-ms="63" status="PASS">
          <reporter-output>
          </reporter-output>
        </test-method> <!-- beforeMethod -->
        <test-method retried="true" signature="testMultipleUserDetials(java.lang.String,java.lang.String)[pri:1, instance:testng.NewTest@378542de]" started-at="2022-10-15T00:11:28 IST" name="testMultipleUserDetials" data-provider="loginDetails" finished-at="2022-10-15T00:11:29 IST" depends-on-methods="testng.NewTest.validLogin" duration-ms="799" status="SKIP">
          <params>
            <param index="0">
              <value>
                <![CDATA[locked_out_user]]>
              </value>
            </param>
            <param index="1">
              <value>
                <![CDATA[rrr]]>
              </value>
            </param>
          </params>
          <exception class="java.lang.AssertionError">
            <message>
              <![CDATA[expected [true] but found [false]]]>
            </message>
            <full-stacktrace>
              <![CDATA[java.lang.AssertionError: expected [true] but found [false]
at org.testng.Assert.fail(Assert.java:110)
at org.testng.Assert.failNotEquals(Assert.java:1413)
at org.testng.Assert.assertEqualsImpl(Assert.java:149)
at org.testng.Assert.assertEquals(Assert.java:131)
at org.testng.Assert.assertEquals(Assert.java:1020)
at testng.NewTest.testMultipleUserDetials(NewTest.java:48)
at java.base/jdk.internal.reflect.DirectMethodHandleAccessor.invoke(DirectMethodHandleAccessor.java:104)
at java.base/java.lang.reflect.Method.invoke(Method.java:578)
at org.testng.internal.invokers.MethodInvocationHelper.invokeMethod(MethodInvocationHelper.java:139)
at org.testng.internal.invokers.TestInvoker.invokeMethod(TestInvoker.java:677)
at org.testng.internal.invokers.TestInvoker.retryFailed(TestInvoker.java:263)
at org.testng.internal.invokers.MethodRunner.runInSequence(MethodRunner.java:62)
at org.testng.internal.invokers.TestInvoker$MethodInvocationAgent.invoke(TestInvoker.java:962)
at org.testng.internal.invokers.TestInvoker.invokeTestMethods(TestInvoker.java:194)
at org.testng.internal.invokers.TestMethodWorker.invokeTestMethods(TestMethodWorker.java:148)
at org.testng.internal.invokers.TestMethodWorker.run(TestMethodWorker.java:128)
at java.base/java.util.ArrayList.forEach(ArrayList.java:1511)
at org.testng.TestRunner.privateRun(TestRunner.java:806)
at org.testng.TestRunner.run(TestRunner.java:601)
at org.testng.SuiteRunner.runTest(SuiteRunner.java:433)
at org.testng.SuiteRunner.runSequentially(SuiteRunner.java:427)
at org.testng.SuiteRunner.privateRun(SuiteRunner.java:387)
at org.testng.SuiteRunner.run(SuiteRunner.java:330)
at org.testng.SuiteRunnerWorker.runSuite(SuiteRunnerWorker.java:52)
at org.testng.SuiteRunnerWorker.run(SuiteRunnerWorker.java:95)
at org.testng.TestNG.runSuitesSequentially(TestNG.java:1256)
at org.testng.TestNG.runSuitesLocally(TestNG.java:1176)
at org.testng.TestNG.runSuites(TestNG.java:1099)
at org.testng.TestNG.run(TestNG.java:1067)
at org.testng.remote.AbstractRemoteTestNG.run(AbstractRemoteTestNG.java:115)
at org.testng.remote.RemoteTestNG.initAndRun(RemoteTestNG.java:251)
at org.testng.remote.RemoteTestNG.main(RemoteTestNG.java:77)
]]>
            </full-stacktrace>
          </exception> <!-- java.lang.AssertionError -->
          <reporter-output>
          </reporter-output>
        </test-method> <!-- testMultipleUserDetials -->
        <test-method is-config="true" signature="beforeMethod()[pri:0, instance:testng.NewTest@378542de]" started-at="2022-10-15T00:11:29 IST" name="beforeMethod" finished-at="2022-10-15T00:11:29 IST" duration-ms="50" status="PASS">
          <reporter-output>
          </reporter-output>
        </test-method> <!-- beforeMethod -->
        <test-method retried="true" signature="testMultipleUserDetials(java.lang.String,java.lang.String)[pri:1, instance:testng.NewTest@378542de]" started-at="2022-10-15T00:11:29 IST" name="testMultipleUserDetials" data-provider="loginDetails" finished-at="2022-10-15T00:11:30 IST" depends-on-methods="testng.NewTest.validLogin" duration-ms="841" status="SKIP">
          <params>
            <param index="0">
              <value>
                <![CDATA[locked_out_user]]>
              </value>
            </param>
            <param index="1">
              <value>
                <![CDATA[rrr]]>
              </value>
            </param>
          </params>
          <exception class="java.lang.AssertionError">
            <message>
              <![CDATA[expected [true] but found [false]]]>
            </message>
            <full-stacktrace>
              <![CDATA[java.lang.AssertionError: expected [true] but found [false]
at org.testng.Assert.fail(Assert.java:110)
at org.testng.Assert.failNotEquals(Assert.java:1413)
at org.testng.Assert.assertEqualsImpl(Assert.java:149)
at org.testng.Assert.assertEquals(Assert.java:131)
at org.testng.Assert.assertEquals(Assert.java:1020)
at testng.NewTest.testMultipleUserDetials(NewTest.java:48)
at java.base/jdk.internal.reflect.DirectMethodHandleAccessor.invoke(DirectMethodHandleAccessor.java:104)
at java.base/java.lang.reflect.Method.invoke(Method.java:578)
at org.testng.internal.invokers.MethodInvocationHelper.invokeMethod(MethodInvocationHelper.java:139)
at org.testng.internal.invokers.TestInvoker.invokeMethod(TestInvoker.java:677)
at org.testng.internal.invokers.TestInvoker.retryFailed(TestInvoker.java:263)
at org.testng.internal.invokers.MethodRunner.runInSequence(MethodRunner.java:62)
at org.testng.internal.invokers.TestInvoker$MethodInvocationAgent.invoke(TestInvoker.java:962)
at org.testng.internal.invokers.TestInvoker.invokeTestMethods(TestInvoker.java:194)
at org.testng.internal.invokers.TestMethodWorker.invokeTestMethods(TestMethodWorker.java:148)
at org.testng.internal.invokers.TestMethodWorker.run(TestMethodWorker.java:128)
at java.base/java.util.ArrayList.forEach(ArrayList.java:1511)
at org.testng.TestRunner.privateRun(TestRunner.java:806)
at org.testng.TestRunner.run(TestRunner.java:601)
at org.testng.SuiteRunner.runTest(SuiteRunner.java:433)
at org.testng.SuiteRunner.runSequentially(SuiteRunner.java:427)
at org.testng.SuiteRunner.privateRun(SuiteRunner.java:387)
at org.testng.SuiteRunner.run(SuiteRunner.java:330)
at org.testng.SuiteRunnerWorker.runSuite(SuiteRunnerWorker.java:52)
at org.testng.SuiteRunnerWorker.run(SuiteRunnerWorker.java:95)
at org.testng.TestNG.runSuitesSequentially(TestNG.java:1256)
at org.testng.TestNG.runSuitesLocally(TestNG.java:1176)
at org.testng.TestNG.runSuites(TestNG.java:1099)
at org.testng.TestNG.run(TestNG.java:1067)
at org.testng.remote.AbstractRemoteTestNG.run(AbstractRemoteTestNG.java:115)
at org.testng.remote.RemoteTestNG.initAndRun(RemoteTestNG.java:251)
at org.testng.remote.RemoteTestNG.main(RemoteTestNG.java:77)
]]>
            </full-stacktrace>
          </exception> <!-- java.lang.AssertionError -->
          <reporter-output>
          </reporter-output>
        </test-method> <!-- testMultipleUserDetials -->
        <test-method is-config="true" signature="beforeMethod()[pri:0, instance:testng.NewTest@378542de]" started-at="2022-10-15T00:11:30 IST" name="beforeMethod" finished-at="2022-10-15T00:11:30 IST" duration-ms="84" status="PASS">
          <reporter-output>
          </reporter-output>
        </test-method> <!-- beforeMethod -->
        <test-method retried="true" signature="testMultipleUserDetials(java.lang.String,java.lang.String)[pri:1, instance:testng.NewTest@378542de]" started-at="2022-10-15T00:11:30 IST" name="testMultipleUserDetials" data-provider="loginDetails" finished-at="2022-10-15T00:11:31 IST" depends-on-methods="testng.NewTest.validLogin" duration-ms="771" status="SKIP">
          <params>
            <param index="0">
              <value>
                <![CDATA[locked_out_user]]>
              </value>
            </param>
            <param index="1">
              <value>
                <![CDATA[rrr]]>
              </value>
            </param>
          </params>
          <exception class="java.lang.AssertionError">
            <message>
              <![CDATA[expected [true] but found [false]]]>
            </message>
            <full-stacktrace>
              <![CDATA[java.lang.AssertionError: expected [true] but found [false]
at org.testng.Assert.fail(Assert.java:110)
at org.testng.Assert.failNotEquals(Assert.java:1413)
at org.testng.Assert.assertEqualsImpl(Assert.java:149)
at org.testng.Assert.assertEquals(Assert.java:131)
at org.testng.Assert.assertEquals(Assert.java:1020)
at testng.NewTest.testMultipleUserDetials(NewTest.java:48)
at java.base/jdk.internal.reflect.DirectMethodHandleAccessor.invoke(DirectMethodHandleAccessor.java:104)
at java.base/java.lang.reflect.Method.invoke(Method.java:578)
at org.testng.internal.invokers.MethodInvocationHelper.invokeMethod(MethodInvocationHelper.java:139)
at org.testng.internal.invokers.TestInvoker.invokeMethod(TestInvoker.java:677)
at org.testng.internal.invokers.TestInvoker.retryFailed(TestInvoker.java:263)
at org.testng.internal.invokers.MethodRunner.runInSequence(MethodRunner.java:62)
at org.testng.internal.invokers.TestInvoker$MethodInvocationAgent.invoke(TestInvoker.java:962)
at org.testng.internal.invokers.TestInvoker.invokeTestMethods(TestInvoker.java:194)
at org.testng.internal.invokers.TestMethodWorker.invokeTestMethods(TestMethodWorker.java:148)
at org.testng.internal.invokers.TestMethodWorker.run(TestMethodWorker.java:128)
at java.base/java.util.ArrayList.forEach(ArrayList.java:1511)
at org.testng.TestRunner.privateRun(TestRunner.java:806)
at org.testng.TestRunner.run(TestRunner.java:601)
at org.testng.SuiteRunner.runTest(SuiteRunner.java:433)
at org.testng.SuiteRunner.runSequentially(SuiteRunner.java:427)
at org.testng.SuiteRunner.privateRun(SuiteRunner.java:387)
at org.testng.SuiteRunner.run(SuiteRunner.java:330)
at org.testng.SuiteRunnerWorker.runSuite(SuiteRunnerWorker.java:52)
at org.testng.SuiteRunnerWorker.run(SuiteRunnerWorker.java:95)
at org.testng.TestNG.runSuitesSequentially(TestNG.java:1256)
at org.testng.TestNG.runSuitesLocally(TestNG.java:1176)
at org.testng.TestNG.runSuites(TestNG.java:1099)
at org.testng.TestNG.run(TestNG.java:1067)
at org.testng.remote.AbstractRemoteTestNG.run(AbstractRemoteTestNG.java:115)
at org.testng.remote.RemoteTestNG.initAndRun(RemoteTestNG.java:251)
at org.testng.remote.RemoteTestNG.main(RemoteTestNG.java:77)
]]>
            </full-stacktrace>
          </exception> <!-- java.lang.AssertionError -->
          <reporter-output>
          </reporter-output>
        </test-method> <!-- testMultipleUserDetials -->
        <test-method is-config="true" signature="beforeMethod()[pri:0, instance:testng.NewTest@378542de]" started-at="2022-10-15T00:11:31 IST" name="beforeMethod" finished-at="2022-10-15T00:11:31 IST" duration-ms="59" status="PASS">
          <reporter-output>
          </reporter-output>
        </test-method> <!-- beforeMethod -->
        <test-method signature="testMultipleUserDetials(java.lang.String,java.lang.String)[pri:1, instance:testng.NewTest@378542de]" started-at="2022-10-15T00:11:31 IST" name="testMultipleUserDetials" data-provider="loginDetails" finished-at="2022-10-15T00:11:31 IST" depends-on-methods="testng.NewTest.validLogin" duration-ms="788" status="FAIL">
          <params>
            <param index="0">
              <value>
                <![CDATA[locked_out_user]]>
              </value>
            </param>
            <param index="1">
              <value>
                <![CDATA[rrr]]>
              </value>
            </param>
          </params>
          <exception class="java.lang.AssertionError">
            <message>
              <![CDATA[expected [true] but found [false]]]>
            </message>
            <full-stacktrace>
              <![CDATA[java.lang.AssertionError: expected [true] but found [false]
at org.testng.Assert.fail(Assert.java:110)
at org.testng.Assert.failNotEquals(Assert.java:1413)
at org.testng.Assert.assertEqualsImpl(Assert.java:149)
at org.testng.Assert.assertEquals(Assert.java:131)
at org.testng.Assert.assertEquals(Assert.java:1020)
at testng.NewTest.testMultipleUserDetials(NewTest.java:48)
at java.base/jdk.internal.reflect.DirectMethodHandleAccessor.invoke(DirectMethodHandleAccessor.java:104)
at java.base/java.lang.reflect.Method.invoke(Method.java:578)
at org.testng.internal.invokers.MethodInvocationHelper.invokeMethod(MethodInvocationHelper.java:139)
at org.testng.internal.invokers.TestInvoker.invokeMethod(TestInvoker.java:677)
at org.testng.internal.invokers.TestInvoker.retryFailed(TestInvoker.java:263)
at org.testng.internal.invokers.MethodRunner.runInSequence(MethodRunner.java:62)
at org.testng.internal.invokers.TestInvoker$MethodInvocationAgent.invoke(TestInvoker.java:962)
at org.testng.internal.invokers.TestInvoker.invokeTestMethods(TestInvoker.java:194)
at org.testng.internal.invokers.TestMethodWorker.invokeTestMethods(TestMethodWorker.java:148)
at org.testng.internal.invokers.TestMethodWorker.run(TestMethodWorker.java:128)
at java.base/java.util.ArrayList.forEach(ArrayList.java:1511)
at org.testng.TestRunner.privateRun(TestRunner.java:806)
at org.testng.TestRunner.run(TestRunner.java:601)
at org.testng.SuiteRunner.runTest(SuiteRunner.java:433)
at org.testng.SuiteRunner.runSequentially(SuiteRunner.java:427)
at org.testng.SuiteRunner.privateRun(SuiteRunner.java:387)
at org.testng.SuiteRunner.run(SuiteRunner.java:330)
at org.testng.SuiteRunnerWorker.runSuite(SuiteRunnerWorker.java:52)
at org.testng.SuiteRunnerWorker.run(SuiteRunnerWorker.java:95)
at org.testng.TestNG.runSuitesSequentially(TestNG.java:1256)
at org.testng.TestNG.runSuitesLocally(TestNG.java:1176)
at org.testng.TestNG.runSuites(TestNG.java:1099)
at org.testng.TestNG.run(TestNG.java:1067)
at org.testng.remote.AbstractRemoteTestNG.run(AbstractRemoteTestNG.java:115)
at org.testng.remote.RemoteTestNG.initAndRun(RemoteTestNG.java:251)
at org.testng.remote.RemoteTestNG.main(RemoteTestNG.java:77)
]]>
            </full-stacktrace>
          </exception> <!-- java.lang.AssertionError -->
          <reporter-output>
          </reporter-output>
        </test-method> <!-- testMultipleUserDetials -->
        <test-method is-config="true" signature="beforeMethod()[pri:0, instance:testng.NewTest@378542de]" started-at="2022-10-15T00:11:31 IST" name="beforeMethod" finished-at="2022-10-15T00:11:31 IST" duration-ms="68" status="PASS">
          <reporter-output>
          </reporter-output>
        </test-method> <!-- beforeMethod -->
        <test-method signature="testMultipleUserDetials(java.lang.String,java.lang.String)[pri:1, instance:testng.NewTest@378542de]" started-at="2022-10-15T00:11:31 IST" name="testMultipleUserDetials" data-provider="loginDetails" finished-at="2022-10-15T00:11:32 IST" depends-on-methods="testng.NewTest.validLogin" duration-ms="852" status="PASS">
          <params>
            <param index="0">
              <value>
                <![CDATA[problem_user]]>
              </value>
            </param>
            <param index="1">
              <value>
                <![CDATA[secret_sauce]]>
              </value>
            </param>
          </params>
          <reporter-output>
          </reporter-output>
        </test-method> <!-- testMultipleUserDetials -->
        <test-method is-config="true" signature="beforeMethod()[pri:0, instance:testng.NewTest@378542de]" started-at="2022-10-15T00:11:32 IST" name="beforeMethod" finished-at="2022-10-15T00:11:32 IST" duration-ms="80" status="PASS">
          <reporter-output>
          </reporter-output>
        </test-method> <!-- beforeMethod -->
        <test-method retried="true" signature="testMultipleUserDetials(java.lang.String,java.lang.String)[pri:1, instance:testng.NewTest@378542de]" started-at="2022-10-15T00:11:32 IST" name="testMultipleUserDetials" data-provider="loginDetails" finished-at="2022-10-15T00:11:33 IST" depends-on-methods="testng.NewTest.validLogin" duration-ms="874" status="SKIP">
          <params>
            <param index="0">
              <value>
                <![CDATA[performance_glitch_user]]>
              </value>
            </param>
            <param index="1">
              <value>
                <![CDATA[rrr]]>
              </value>
            </param>
          </params>
          <exception class="java.lang.AssertionError">
            <message>
              <![CDATA[expected [true] but found [false]]]>
            </message>
            <full-stacktrace>
              <![CDATA[java.lang.AssertionError: expected [true] but found [false]
at org.testng.Assert.fail(Assert.java:110)
at org.testng.Assert.failNotEquals(Assert.java:1413)
at org.testng.Assert.assertEqualsImpl(Assert.java:149)
at org.testng.Assert.assertEquals(Assert.java:131)
at org.testng.Assert.assertEquals(Assert.java:1020)
at testng.NewTest.testMultipleUserDetials(NewTest.java:48)
at java.base/jdk.internal.reflect.DirectMethodHandleAccessor.invoke(DirectMethodHandleAccessor.java:104)
at java.base/java.lang.reflect.Method.invoke(Method.java:578)
at org.testng.internal.invokers.MethodInvocationHelper.invokeMethod(MethodInvocationHelper.java:139)
at org.testng.internal.invokers.TestInvoker.invokeMethod(TestInvoker.java:677)
at org.testng.internal.invokers.TestInvoker.invokeTestMethod(TestInvoker.java:221)
at org.testng.internal.invokers.MethodRunner.runInSequence(MethodRunner.java:50)
at org.testng.internal.invokers.TestInvoker$MethodInvocationAgent.invoke(TestInvoker.java:962)
at org.testng.internal.invokers.TestInvoker.invokeTestMethods(TestInvoker.java:194)
at org.testng.internal.invokers.TestMethodWorker.invokeTestMethods(TestMethodWorker.java:148)
at org.testng.internal.invokers.TestMethodWorker.run(TestMethodWorker.java:128)
at java.base/java.util.ArrayList.forEach(ArrayList.java:1511)
at org.testng.TestRunner.privateRun(TestRunner.java:806)
at org.testng.TestRunner.run(TestRunner.java:601)
at org.testng.SuiteRunner.runTest(SuiteRunner.java:433)
at org.testng.SuiteRunner.runSequentially(SuiteRunner.java:427)
at org.testng.SuiteRunner.privateRun(SuiteRunner.java:387)
at org.testng.SuiteRunner.run(SuiteRunner.java:330)
at org.testng.SuiteRunnerWorker.runSuite(SuiteRunnerWorker.java:52)
at org.testng.SuiteRunnerWorker.run(SuiteRunnerWorker.java:95)
at org.testng.TestNG.runSuitesSequentially(TestNG.java:1256)
at org.testng.TestNG.runSuitesLocally(TestNG.java:1176)
at org.testng.TestNG.runSuites(TestNG.java:1099)
at org.testng.TestNG.run(TestNG.java:1067)
at org.testng.remote.AbstractRemoteTestNG.run(AbstractRemoteTestNG.java:115)
at org.testng.remote.RemoteTestNG.initAndRun(RemoteTestNG.java:251)
at org.testng.remote.RemoteTestNG.main(RemoteTestNG.java:77)
]]>
            </full-stacktrace>
          </exception> <!-- java.lang.AssertionError -->
          <reporter-output>
          </reporter-output>
        </test-method> <!-- testMultipleUserDetials -->
        <test-method is-config="true" signature="beforeMethod()[pri:0, instance:testng.NewTest@378542de]" started-at="2022-10-15T00:11:33 IST" name="beforeMethod" finished-at="2022-10-15T00:11:33 IST" duration-ms="47" status="PASS">
          <reporter-output>
          </reporter-output>
        </test-method> <!-- beforeMethod -->
        <test-method retried="true" signature="testMultipleUserDetials(java.lang.String,java.lang.String)[pri:1, instance:testng.NewTest@378542de]" started-at="2022-10-15T00:11:33 IST" name="testMultipleUserDetials" data-provider="loginDetails" finished-at="2022-10-15T00:11:34 IST" depends-on-methods="testng.NewTest.validLogin" duration-ms="820" status="SKIP">
          <params>
            <param index="0">
              <value>
                <![CDATA[performance_glitch_user]]>
              </value>
            </param>
            <param index="1">
              <value>
                <![CDATA[rrr]]>
              </value>
            </param>
          </params>
          <exception class="java.lang.AssertionError">
            <message>
              <![CDATA[expected [true] but found [false]]]>
            </message>
            <full-stacktrace>
              <![CDATA[java.lang.AssertionError: expected [true] but found [false]
at org.testng.Assert.fail(Assert.java:110)
at org.testng.Assert.failNotEquals(Assert.java:1413)
at org.testng.Assert.assertEqualsImpl(Assert.java:149)
at org.testng.Assert.assertEquals(Assert.java:131)
at org.testng.Assert.assertEquals(Assert.java:1020)
at testng.NewTest.testMultipleUserDetials(NewTest.java:48)
at java.base/jdk.internal.reflect.DirectMethodHandleAccessor.invoke(DirectMethodHandleAccessor.java:104)
at java.base/java.lang.reflect.Method.invoke(Method.java:578)
at org.testng.internal.invokers.MethodInvocationHelper.invokeMethod(MethodInvocationHelper.java:139)
at org.testng.internal.invokers.TestInvoker.invokeMethod(TestInvoker.java:677)
at org.testng.internal.invokers.TestInvoker.retryFailed(TestInvoker.java:263)
at org.testng.internal.invokers.MethodRunner.runInSequence(MethodRunner.java:62)
at org.testng.internal.invokers.TestInvoker$MethodInvocationAgent.invoke(TestInvoker.java:962)
at org.testng.internal.invokers.TestInvoker.invokeTestMethods(TestInvoker.java:194)
at org.testng.internal.invokers.TestMethodWorker.invokeTestMethods(TestMethodWorker.java:148)
at org.testng.internal.invokers.TestMethodWorker.run(TestMethodWorker.java:128)
at java.base/java.util.ArrayList.forEach(ArrayList.java:1511)
at org.testng.TestRunner.privateRun(TestRunner.java:806)
at org.testng.TestRunner.run(TestRunner.java:601)
at org.testng.SuiteRunner.runTest(SuiteRunner.java:433)
at org.testng.SuiteRunner.runSequentially(SuiteRunner.java:427)
at org.testng.SuiteRunner.privateRun(SuiteRunner.java:387)
at org.testng.SuiteRunner.run(SuiteRunner.java:330)
at org.testng.SuiteRunnerWorker.runSuite(SuiteRunnerWorker.java:52)
at org.testng.SuiteRunnerWorker.run(SuiteRunnerWorker.java:95)
at org.testng.TestNG.runSuitesSequentially(TestNG.java:1256)
at org.testng.TestNG.runSuitesLocally(TestNG.java:1176)
at org.testng.TestNG.runSuites(TestNG.java:1099)
at org.testng.TestNG.run(TestNG.java:1067)
at org.testng.remote.AbstractRemoteTestNG.run(AbstractRemoteTestNG.java:115)
at org.testng.remote.RemoteTestNG.initAndRun(RemoteTestNG.java:251)
at org.testng.remote.RemoteTestNG.main(RemoteTestNG.java:77)
]]>
            </full-stacktrace>
          </exception> <!-- java.lang.AssertionError -->
          <reporter-output>
          </reporter-output>
        </test-method> <!-- testMultipleUserDetials -->
        <test-method is-config="true" signature="beforeMethod()[pri:0, instance:testng.NewTest@378542de]" started-at="2022-10-15T00:11:34 IST" name="beforeMethod" finished-at="2022-10-15T00:11:34 IST" duration-ms="75" status="PASS">
          <reporter-output>
          </reporter-output>
        </test-method> <!-- beforeMethod -->
        <test-method retried="true" signature="testMultipleUserDetials(java.lang.String,java.lang.String)[pri:1, instance:testng.NewTest@378542de]" started-at="2022-10-15T00:11:34 IST" name="testMultipleUserDetials" data-provider="loginDetails" finished-at="2022-10-15T00:11:35 IST" depends-on-methods="testng.NewTest.validLogin" duration-ms="833" status="SKIP">
          <params>
            <param index="0">
              <value>
                <![CDATA[performance_glitch_user]]>
              </value>
            </param>
            <param index="1">
              <value>
                <![CDATA[rrr]]>
              </value>
            </param>
          </params>
          <exception class="java.lang.AssertionError">
            <message>
              <![CDATA[expected [true] but found [false]]]>
            </message>
            <full-stacktrace>
              <![CDATA[java.lang.AssertionError: expected [true] but found [false]
at org.testng.Assert.fail(Assert.java:110)
at org.testng.Assert.failNotEquals(Assert.java:1413)
at org.testng.Assert.assertEqualsImpl(Assert.java:149)
at org.testng.Assert.assertEquals(Assert.java:131)
at org.testng.Assert.assertEquals(Assert.java:1020)
at testng.NewTest.testMultipleUserDetials(NewTest.java:48)
at java.base/jdk.internal.reflect.DirectMethodHandleAccessor.invoke(DirectMethodHandleAccessor.java:104)
at java.base/java.lang.reflect.Method.invoke(Method.java:578)
at org.testng.internal.invokers.MethodInvocationHelper.invokeMethod(MethodInvocationHelper.java:139)
at org.testng.internal.invokers.TestInvoker.invokeMethod(TestInvoker.java:677)
at org.testng.internal.invokers.TestInvoker.retryFailed(TestInvoker.java:263)
at org.testng.internal.invokers.MethodRunner.runInSequence(MethodRunner.java:62)
at org.testng.internal.invokers.TestInvoker$MethodInvocationAgent.invoke(TestInvoker.java:962)
at org.testng.internal.invokers.TestInvoker.invokeTestMethods(TestInvoker.java:194)
at org.testng.internal.invokers.TestMethodWorker.invokeTestMethods(TestMethodWorker.java:148)
at org.testng.internal.invokers.TestMethodWorker.run(TestMethodWorker.java:128)
at java.base/java.util.ArrayList.forEach(ArrayList.java:1511)
at org.testng.TestRunner.privateRun(TestRunner.java:806)
at org.testng.TestRunner.run(TestRunner.java:601)
at org.testng.SuiteRunner.runTest(SuiteRunner.java:433)
at org.testng.SuiteRunner.runSequentially(SuiteRunner.java:427)
at org.testng.SuiteRunner.privateRun(SuiteRunner.java:387)
at org.testng.SuiteRunner.run(SuiteRunner.java:330)
at org.testng.SuiteRunnerWorker.runSuite(SuiteRunnerWorker.java:52)
at org.testng.SuiteRunnerWorker.run(SuiteRunnerWorker.java:95)
at org.testng.TestNG.runSuitesSequentially(TestNG.java:1256)
at org.testng.TestNG.runSuitesLocally(TestNG.java:1176)
at org.testng.TestNG.runSuites(TestNG.java:1099)
at org.testng.TestNG.run(TestNG.java:1067)
at org.testng.remote.AbstractRemoteTestNG.run(AbstractRemoteTestNG.java:115)
at org.testng.remote.RemoteTestNG.initAndRun(RemoteTestNG.java:251)
at org.testng.remote.RemoteTestNG.main(RemoteTestNG.java:77)
]]>
            </full-stacktrace>
          </exception> <!-- java.lang.AssertionError -->
          <reporter-output>
          </reporter-output>
        </test-method> <!-- testMultipleUserDetials -->
        <test-method is-config="true" signature="beforeMethod()[pri:0, instance:testng.NewTest@378542de]" started-at="2022-10-15T00:11:35 IST" name="beforeMethod" finished-at="2022-10-15T00:11:35 IST" duration-ms="64" status="PASS">
          <reporter-output>
          </reporter-output>
        </test-method> <!-- beforeMethod -->
        <test-method retried="true" signature="testMultipleUserDetials(java.lang.String,java.lang.String)[pri:1, instance:testng.NewTest@378542de]" started-at="2022-10-15T00:11:35 IST" name="testMultipleUserDetials" data-provider="loginDetails" finished-at="2022-10-15T00:11:36 IST" depends-on-methods="testng.NewTest.validLogin" duration-ms="893" status="SKIP">
          <params>
            <param index="0">
              <value>
                <![CDATA[performance_glitch_user]]>
              </value>
            </param>
            <param index="1">
              <value>
                <![CDATA[rrr]]>
              </value>
            </param>
          </params>
          <exception class="java.lang.AssertionError">
            <message>
              <![CDATA[expected [true] but found [false]]]>
            </message>
            <full-stacktrace>
              <![CDATA[java.lang.AssertionError: expected [true] but found [false]
at org.testng.Assert.fail(Assert.java:110)
at org.testng.Assert.failNotEquals(Assert.java:1413)
at org.testng.Assert.assertEqualsImpl(Assert.java:149)
at org.testng.Assert.assertEquals(Assert.java:131)
at org.testng.Assert.assertEquals(Assert.java:1020)
at testng.NewTest.testMultipleUserDetials(NewTest.java:48)
at java.base/jdk.internal.reflect.DirectMethodHandleAccessor.invoke(DirectMethodHandleAccessor.java:104)
at java.base/java.lang.reflect.Method.invoke(Method.java:578)
at org.testng.internal.invokers.MethodInvocationHelper.invokeMethod(MethodInvocationHelper.java:139)
at org.testng.internal.invokers.TestInvoker.invokeMethod(TestInvoker.java:677)
at org.testng.internal.invokers.TestInvoker.retryFailed(TestInvoker.java:263)
at org.testng.internal.invokers.MethodRunner.runInSequence(MethodRunner.java:62)
at org.testng.internal.invokers.TestInvoker$MethodInvocationAgent.invoke(TestInvoker.java:962)
at org.testng.internal.invokers.TestInvoker.invokeTestMethods(TestInvoker.java:194)
at org.testng.internal.invokers.TestMethodWorker.invokeTestMethods(TestMethodWorker.java:148)
at org.testng.internal.invokers.TestMethodWorker.run(TestMethodWorker.java:128)
at java.base/java.util.ArrayList.forEach(ArrayList.java:1511)
at org.testng.TestRunner.privateRun(TestRunner.java:806)
at org.testng.TestRunner.run(TestRunner.java:601)
at org.testng.SuiteRunner.runTest(SuiteRunner.java:433)
at org.testng.SuiteRunner.runSequentially(SuiteRunner.java:427)
at org.testng.SuiteRunner.privateRun(SuiteRunner.java:387)
at org.testng.SuiteRunner.run(SuiteRunner.java:330)
at org.testng.SuiteRunnerWorker.runSuite(SuiteRunnerWorker.java:52)
at org.testng.SuiteRunnerWorker.run(SuiteRunnerWorker.java:95)
at org.testng.TestNG.runSuitesSequentially(TestNG.java:1256)
at org.testng.TestNG.runSuitesLocally(TestNG.java:1176)
at org.testng.TestNG.runSuites(TestNG.java:1099)
at org.testng.TestNG.run(TestNG.java:1067)
at org.testng.remote.AbstractRemoteTestNG.run(AbstractRemoteTestNG.java:115)
at org.testng.remote.RemoteTestNG.initAndRun(RemoteTestNG.java:251)
at org.testng.remote.RemoteTestNG.main(RemoteTestNG.java:77)
]]>
            </full-stacktrace>
          </exception> <!-- java.lang.AssertionError -->
          <reporter-output>
          </reporter-output>
        </test-method> <!-- testMultipleUserDetials -->
        <test-method is-config="true" signature="beforeMethod()[pri:0, instance:testng.NewTest@378542de]" started-at="2022-10-15T00:11:36 IST" name="beforeMethod" finished-at="2022-10-15T00:11:36 IST" duration-ms="59" status="PASS">
          <reporter-output>
          </reporter-output>
        </test-method> <!-- beforeMethod -->
        <test-method retried="true" signature="testMultipleUserDetials(java.lang.String,java.lang.String)[pri:1, instance:testng.NewTest@378542de]" started-at="2022-10-15T00:11:36 IST" name="testMultipleUserDetials" data-provider="loginDetails" finished-at="2022-10-15T00:11:37 IST" depends-on-methods="testng.NewTest.validLogin" duration-ms="797" status="SKIP">
          <params>
            <param index="0">
              <value>
                <![CDATA[performance_glitch_user]]>
              </value>
            </param>
            <param index="1">
              <value>
                <![CDATA[rrr]]>
              </value>
            </param>
          </params>
          <exception class="java.lang.AssertionError">
            <message>
              <![CDATA[expected [true] but found [false]]]>
            </message>
            <full-stacktrace>
              <![CDATA[java.lang.AssertionError: expected [true] but found [false]
at org.testng.Assert.fail(Assert.java:110)
at org.testng.Assert.failNotEquals(Assert.java:1413)
at org.testng.Assert.assertEqualsImpl(Assert.java:149)
at org.testng.Assert.assertEquals(Assert.java:131)
at org.testng.Assert.assertEquals(Assert.java:1020)
at testng.NewTest.testMultipleUserDetials(NewTest.java:48)
at java.base/jdk.internal.reflect.DirectMethodHandleAccessor.invoke(DirectMethodHandleAccessor.java:104)
at java.base/java.lang.reflect.Method.invoke(Method.java:578)
at org.testng.internal.invokers.MethodInvocationHelper.invokeMethod(MethodInvocationHelper.java:139)
at org.testng.internal.invokers.TestInvoker.invokeMethod(TestInvoker.java:677)
at org.testng.internal.invokers.TestInvoker.retryFailed(TestInvoker.java:263)
at org.testng.internal.invokers.MethodRunner.runInSequence(MethodRunner.java:62)
at org.testng.internal.invokers.TestInvoker$MethodInvocationAgent.invoke(TestInvoker.java:962)
at org.testng.internal.invokers.TestInvoker.invokeTestMethods(TestInvoker.java:194)
at org.testng.internal.invokers.TestMethodWorker.invokeTestMethods(TestMethodWorker.java:148)
at org.testng.internal.invokers.TestMethodWorker.run(TestMethodWorker.java:128)
at java.base/java.util.ArrayList.forEach(ArrayList.java:1511)
at org.testng.TestRunner.privateRun(TestRunner.java:806)
at org.testng.TestRunner.run(TestRunner.java:601)
at org.testng.SuiteRunner.runTest(SuiteRunner.java:433)
at org.testng.SuiteRunner.runSequentially(SuiteRunner.java:427)
at org.testng.SuiteRunner.privateRun(SuiteRunner.java:387)
at org.testng.SuiteRunner.run(SuiteRunner.java:330)
at org.testng.SuiteRunnerWorker.runSuite(SuiteRunnerWorker.java:52)
at org.testng.SuiteRunnerWorker.run(SuiteRunnerWorker.java:95)
at org.testng.TestNG.runSuitesSequentially(TestNG.java:1256)
at org.testng.TestNG.runSuitesLocally(TestNG.java:1176)
at org.testng.TestNG.runSuites(TestNG.java:1099)
at org.testng.TestNG.run(TestNG.java:1067)
at org.testng.remote.AbstractRemoteTestNG.run(AbstractRemoteTestNG.java:115)
at org.testng.remote.RemoteTestNG.initAndRun(RemoteTestNG.java:251)
at org.testng.remote.RemoteTestNG.main(RemoteTestNG.java:77)
]]>
            </full-stacktrace>
          </exception> <!-- java.lang.AssertionError -->
          <reporter-output>
          </reporter-output>
        </test-method> <!-- testMultipleUserDetials -->
        <test-method is-config="true" signature="beforeMethod()[pri:0, instance:testng.NewTest@378542de]" started-at="2022-10-15T00:11:37 IST" name="beforeMethod" finished-at="2022-10-15T00:11:37 IST" duration-ms="78" status="PASS">
          <reporter-output>
          </reporter-output>
        </test-method> <!-- beforeMethod -->
        <test-method signature="testMultipleUserDetials(java.lang.String,java.lang.String)[pri:1, instance:testng.NewTest@378542de]" started-at="2022-10-15T00:11:37 IST" name="testMultipleUserDetials" data-provider="loginDetails" finished-at="2022-10-15T00:11:38 IST" depends-on-methods="testng.NewTest.validLogin" duration-ms="821" status="FAIL">
          <params>
            <param index="0">
              <value>
                <![CDATA[performance_glitch_user]]>
              </value>
            </param>
            <param index="1">
              <value>
                <![CDATA[rrr]]>
              </value>
            </param>
          </params>
          <exception class="java.lang.AssertionError">
            <message>
              <![CDATA[expected [true] but found [false]]]>
            </message>
            <full-stacktrace>
              <![CDATA[java.lang.AssertionError: expected [true] but found [false]
at org.testng.Assert.fail(Assert.java:110)
at org.testng.Assert.failNotEquals(Assert.java:1413)
at org.testng.Assert.assertEqualsImpl(Assert.java:149)
at org.testng.Assert.assertEquals(Assert.java:131)
at org.testng.Assert.assertEquals(Assert.java:1020)
at testng.NewTest.testMultipleUserDetials(NewTest.java:48)
at java.base/jdk.internal.reflect.DirectMethodHandleAccessor.invoke(DirectMethodHandleAccessor.java:104)
at java.base/java.lang.reflect.Method.invoke(Method.java:578)
at org.testng.internal.invokers.MethodInvocationHelper.invokeMethod(MethodInvocationHelper.java:139)
at org.testng.internal.invokers.TestInvoker.invokeMethod(TestInvoker.java:677)
at org.testng.internal.invokers.TestInvoker.retryFailed(TestInvoker.java:263)
at org.testng.internal.invokers.MethodRunner.runInSequence(MethodRunner.java:62)
at org.testng.internal.invokers.TestInvoker$MethodInvocationAgent.invoke(TestInvoker.java:962)
at org.testng.internal.invokers.TestInvoker.invokeTestMethods(TestInvoker.java:194)
at org.testng.internal.invokers.TestMethodWorker.invokeTestMethods(TestMethodWorker.java:148)
at org.testng.internal.invokers.TestMethodWorker.run(TestMethodWorker.java:128)
at java.base/java.util.ArrayList.forEach(ArrayList.java:1511)
at org.testng.TestRunner.privateRun(TestRunner.java:806)
at org.testng.TestRunner.run(TestRunner.java:601)
at org.testng.SuiteRunner.runTest(SuiteRunner.java:433)
at org.testng.SuiteRunner.runSequentially(SuiteRunner.java:427)
at org.testng.SuiteRunner.privateRun(SuiteRunner.java:387)
at org.testng.SuiteRunner.run(SuiteRunner.java:330)
at org.testng.SuiteRunnerWorker.runSuite(SuiteRunnerWorker.java:52)
at org.testng.SuiteRunnerWorker.run(SuiteRunnerWorker.java:95)
at org.testng.TestNG.runSuitesSequentially(TestNG.java:1256)
at org.testng.TestNG.runSuitesLocally(TestNG.java:1176)
at org.testng.TestNG.runSuites(TestNG.java:1099)
at org.testng.TestNG.run(TestNG.java:1067)
at org.testng.remote.AbstractRemoteTestNG.run(AbstractRemoteTestNG.java:115)
at org.testng.remote.RemoteTestNG.initAndRun(RemoteTestNG.java:251)
at org.testng.remote.RemoteTestNG.main(RemoteTestNG.java:77)
]]>
            </full-stacktrace>
          </exception> <!-- java.lang.AssertionError -->
          <reporter-output>
          </reporter-output>
        </test-method> <!-- testMultipleUserDetials -->
        <test-method is-config="true" signature="afterTest()[pri:0, instance:testng.NewTest@378542de]" started-at="2022-10-15T00:11:38 IST" name="afterTest" finished-at="2022-10-15T00:11:39 IST" duration-ms="688" status="PASS">
          <reporter-output>
          </reporter-output>
        </test-method> <!-- afterTest -->
        <test-method is-config="true" signature="afterSuite()[pri:0, instance:testng.NewTest@378542de]" started-at="2022-10-15T00:11:39 IST" name="afterSuite" finished-at="2022-10-15T00:11:39 IST" duration-ms="74" status="PASS">
          <reporter-output>
          </reporter-output>
        </test-method> <!-- afterSuite -->
      </class> <!-- testng.NewTest -->
    </test> <!-- Test -->
  </suite> <!-- Suite -->
</testng-results>
